<?xml version="1.0" encoding="UTF-8"?>
<!-- Generated by org.testng.reporters.JUnitXMLReporter -->
<testsuite ignored="0" hostname="LTIN236815" failures="1" tests="10" name="UrbanLadderTestCases" time="39.14" errors="0" timestamp="2024-02-28T16:35:45 IST">
  <testcase classname="testNG.MainTestng" name="Searching_Bookshelves" time="1.96"/>
  <testcase classname="testNG.MainTestng" name="Apply_Slider" time="11.732"/>
  <testcase classname="testNG.MainTestng" name="Exclude_and_Sort" time="5.786"/>
  <testcase classname="testNG.MainTestng" name="Print_Submenu_items_and_productinfo" time="8.604"/>
  <testcase classname="testNG.MainTestng" name="Go_To_GiftCardsSection" time="1.176">
    <failure type="java.lang.AssertionError" message="null">
      <![CDATA[java.lang.AssertionError: null
at testNG.MainTestng.Go_To_GiftCardsSection(MainTestng.java:111)
at java.base/java.util.ArrayList.forEach(ArrayList.java:1511)
... Removed 29 stack frames]]>
    </failure>
  </testcase> <!-- Go_To_GiftCardsSection -->
  <testcase classname="testNG.MainTestng" name="Enter_Amount" time="0.0">
    <skipped/>
  </testcase> <!-- Enter_Amount -->
  <testcase classname="testNG.MainTestng" name="Fill_Form_with_Invalid_info" time="0.0">
    <skipped/>
  </testcase> <!-- Fill_Form_with_Invalid_info -->
  <testcase classname="testNG.MainTestng" name="Capture_ErrorMessage" time="0.0">
    <skipped/>
  </testcase> <!-- Capture_ErrorMessage -->
  <testcase classname="testNG.MainTestng" name="Fill_Form_with_Valid_data" time="0.0">
    <skipped/>
  </testcase> <!-- Fill_Form_with_Valid_data -->
  <testcase classname="testNG.MainTestng" name="Validate_Entered_Details" time="0.0">
    <skipped/>
  </testcase> <!-- Validate_Entered_Details -->
</testsuite> <!-- UrbanLadderTestCases -->
