<?xml version="1.0" encoding="UTF-8"?>
<testng-results ignored="0" total="10" passed="4" failed="1" skipped="5">
  <reporter-output>
  </reporter-output>
  <suite started-at="2024-02-28T16:35:06 IST" name="Urban_Ladder_Suite" finished-at="2024-02-28T16:35:45 IST" duration-ms="39140">
    <groups>
    </groups>
    <test started-at="2024-02-28T16:35:06 IST" name="UrbanLadderTestCases" finished-at="2024-02-28T16:35:45 IST" duration-ms="39140">
      <class name="testNG.MainTestng">
        <test-method is-config="true" signature="launch(java.lang.String,java.lang.String)[pri:0, instance:testNG.MainTestng@6e9319f]" started-at="2024-02-28T16:35:06 IST" name="launch" finished-at="2024-02-28T16:35:13 IST" duration-ms="7387" status="PASS">
          <params>
            <param index="0">
              <value>
                <![CDATA[Chrome]]>
              </value>
            </param>
            <param index="1">
              <value>
                <![CDATA[https://urbanladder.com/]]>
              </value>
            </param>
          </params>
          <reporter-output>
          </reporter-output>
        </test-method> <!-- launch -->
        <test-method signature="Searching_Bookshelves()[pri:0, instance:testNG.MainTestng@6e9319f]" started-at="2024-02-28T16:35:13 IST" name="Searching_Bookshelves" finished-at="2024-02-28T16:35:15 IST" duration-ms="1960" status="PASS">
          <reporter-output>
          </reporter-output>
        </test-method> <!-- Searching_Bookshelves -->
        <test-method signature="Apply_Slider()[pri:1, instance:testNG.MainTestng@6e9319f]" started-at="2024-02-28T16:35:16 IST" name="Apply_Slider" finished-at="2024-02-28T16:35:27 IST" depends-on-methods="testNG.MainTestng.Searching_Bookshelves" duration-ms="11732" status="PASS">
          <reporter-output>
          </reporter-output>
        </test-method> <!-- Apply_Slider -->
        <test-method signature="Exclude_and_Sort()[pri:2, instance:testNG.MainTestng@6e9319f]" started-at="2024-02-28T16:35:28 IST" name="Exclude_and_Sort" finished-at="2024-02-28T16:35:33 IST" depends-on-methods="testNG.MainTestng.Searching_Bookshelves" duration-ms="5786" status="PASS">
          <reporter-output>
          </reporter-output>
        </test-method> <!-- Exclude_and_Sort -->
        <test-method signature="Print_Submenu_items_and_productinfo()[pri:3, instance:testNG.MainTestng@6e9319f]" started-at="2024-02-28T16:35:34 IST" name="Print_Submenu_items_and_productinfo" finished-at="2024-02-28T16:35:42 IST" depends-on-methods="testNG.MainTestng.Searching_Bookshelves" duration-ms="8604" status="PASS">
          <reporter-output>
          </reporter-output>
        </test-method> <!-- Print_Submenu_items_and_productinfo -->
        <test-method signature="Go_To_GiftCardsSection()[pri:4, instance:testNG.MainTestng@6e9319f]" started-at="2024-02-28T16:35:42 IST" name="Go_To_GiftCardsSection" finished-at="2024-02-28T16:35:44 IST" duration-ms="1176" status="FAIL">
          <exception class="java.lang.AssertionError">
            <message>
              <![CDATA[null]]>
            </message>
            <full-stacktrace>
              <![CDATA[java.lang.AssertionError: null
at org.testng.Assert.fail(Assert.java:110)
at org.testng.Assert.fail(Assert.java:115)
at testNG.MainTestng.Go_To_GiftCardsSection(MainTestng.java:111)
at java.base/jdk.internal.reflect.NativeMethodAccessorImpl.invoke0(Native Method)
at java.base/jdk.internal.reflect.NativeMethodAccessorImpl.invoke(NativeMethodAccessorImpl.java:77)
at java.base/jdk.internal.reflect.DelegatingMethodAccessorImpl.invoke(DelegatingMethodAccessorImpl.java:43)
at java.base/java.lang.reflect.Method.invoke(Method.java:568)
at org.testng.internal.invokers.MethodInvocationHelper.invokeMethod(MethodInvocationHelper.java:136)
at org.testng.internal.invokers.TestInvoker.invokeMethod(TestInvoker.java:658)
at org.testng.internal.invokers.TestInvoker.invokeTestMethod(TestInvoker.java:219)
at org.testng.internal.invokers.MethodRunner.runInSequence(MethodRunner.java:50)
at org.testng.internal.invokers.TestInvoker$MethodInvocationAgent.invoke(TestInvoker.java:923)
at org.testng.internal.invokers.TestInvoker.invokeTestMethods(TestInvoker.java:192)
at org.testng.internal.invokers.TestMethodWorker.invokeTestMethods(TestMethodWorker.java:146)
at org.testng.internal.invokers.TestMethodWorker.run(TestMethodWorker.java:128)
at java.base/java.util.ArrayList.forEach(ArrayList.java:1511)
at org.testng.TestRunner.privateRun(TestRunner.java:808)
at org.testng.TestRunner.run(TestRunner.java:603)
at org.testng.SuiteRunner.runTest(SuiteRunner.java:429)
at org.testng.SuiteRunner.runSequentially(SuiteRunner.java:423)
at org.testng.SuiteRunner.privateRun(SuiteRunner.java:383)
at org.testng.SuiteRunner.run(SuiteRunner.java:326)
at org.testng.SuiteRunnerWorker.runSuite(SuiteRunnerWorker.java:52)
at org.testng.SuiteRunnerWorker.run(SuiteRunnerWorker.java:95)
at org.testng.TestNG.runSuitesSequentially(TestNG.java:1249)
at org.testng.TestNG.runSuitesLocally(TestNG.java:1169)
at org.testng.TestNG.runSuites(TestNG.java:1092)
at org.testng.TestNG.run(TestNG.java:1060)
at org.testng.remote.AbstractRemoteTestNG.run(AbstractRemoteTestNG.java:115)
at org.testng.remote.RemoteTestNG.initAndRun(RemoteTestNG.java:251)
at org.testng.remote.RemoteTestNG.main(RemoteTestNG.java:77)
]]>
            </full-stacktrace>
          </exception> <!-- java.lang.AssertionError -->
          <reporter-output>
          </reporter-output>
        </test-method> <!-- Go_To_GiftCardsSection -->
        <test-method signature="Enter_Amount()[pri:5, instance:testNG.MainTestng@6e9319f]" started-at="2024-02-28T16:35:44 IST" name="Enter_Amount" finished-at="2024-02-28T16:35:44 IST" depends-on-methods="testNG.MainTestng.Go_To_GiftCardsSection" duration-ms="0" status="SKIP">
          <exception class="java.lang.Throwable">
            <message>
              <![CDATA[Method MainTestng.Enter_Amount()[pri:5, instance:testNG.MainTestng@6e9319f] depends on not successfully finished methods]]>
            </message>
            <full-stacktrace>
              <![CDATA[java.lang.Throwable: Method MainTestng.Enter_Amount()[pri:5, instance:testNG.MainTestng@6e9319f] depends on not successfully finished methods
at org.testng.internal.invokers.TestInvoker.invokeTestMethods(TestInvoker.java:148)
at org.testng.internal.invokers.TestMethodWorker.invokeTestMethods(TestMethodWorker.java:146)
at org.testng.internal.invokers.TestMethodWorker.run(TestMethodWorker.java:128)
at java.base/java.util.ArrayList.forEach(ArrayList.java:1511)
at org.testng.TestRunner.privateRun(TestRunner.java:808)
at org.testng.TestRunner.run(TestRunner.java:603)
at org.testng.SuiteRunner.runTest(SuiteRunner.java:429)
at org.testng.SuiteRunner.runSequentially(SuiteRunner.java:423)
at org.testng.SuiteRunner.privateRun(SuiteRunner.java:383)
at org.testng.SuiteRunner.run(SuiteRunner.java:326)
at org.testng.SuiteRunnerWorker.runSuite(SuiteRunnerWorker.java:52)
at org.testng.SuiteRunnerWorker.run(SuiteRunnerWorker.java:95)
at org.testng.TestNG.runSuitesSequentially(TestNG.java:1249)
at org.testng.TestNG.runSuitesLocally(TestNG.java:1169)
at org.testng.TestNG.runSuites(TestNG.java:1092)
at org.testng.TestNG.run(TestNG.java:1060)
at org.testng.remote.AbstractRemoteTestNG.run(AbstractRemoteTestNG.java:115)
at org.testng.remote.RemoteTestNG.initAndRun(RemoteTestNG.java:251)
at org.testng.remote.RemoteTestNG.main(RemoteTestNG.java:77)
]]>
            </full-stacktrace>
          </exception> <!-- java.lang.Throwable -->
          <reporter-output>
          </reporter-output>
        </test-method> <!-- Enter_Amount -->
        <test-method signature="Fill_Form_with_Invalid_info(java.lang.String,java.lang.String,java.lang.String,java.lang.String,java.lang.String,java.lang.String,java.lang.String,java.lang.String)[pri:6, instance:testNG.MainTestng@6e9319f]" started-at="2024-02-28T16:35:44 IST" name="Fill_Form_with_Invalid_info" finished-at="2024-02-28T16:35:44 IST" depends-on-methods="testNG.MainTestng.Enter_Amount" duration-ms="0" status="SKIP">
          <exception class="java.lang.Throwable">
            <message>
              <![CDATA[Method MainTestng.Fill_Form_with_Invalid_info(java.lang.String,java.lang.String,java.lang.String,java.lang.String,java.lang.String,java.lang.String,java.lang.String,java.lang.String)[pri:6, instance:testNG.MainTestng@6e9319f] depends on not successfully finished methods]]>
            </message>
            <full-stacktrace>
              <![CDATA[java.lang.Throwable: Method MainTestng.Fill_Form_with_Invalid_info(java.lang.String,java.lang.String,java.lang.String,java.lang.String,java.lang.String,java.lang.String,java.lang.String,java.lang.String)[pri:6, instance:testNG.MainTestng@6e9319f] depends on not successfully finished methods
at org.testng.internal.invokers.TestInvoker.invokeTestMethods(TestInvoker.java:148)
at org.testng.internal.invokers.TestMethodWorker.invokeTestMethods(TestMethodWorker.java:146)
at org.testng.internal.invokers.TestMethodWorker.run(TestMethodWorker.java:128)
at java.base/java.util.ArrayList.forEach(ArrayList.java:1511)
at org.testng.TestRunner.privateRun(TestRunner.java:808)
at org.testng.TestRunner.run(TestRunner.java:603)
at org.testng.SuiteRunner.runTest(SuiteRunner.java:429)
at org.testng.SuiteRunner.runSequentially(SuiteRunner.java:423)
at org.testng.SuiteRunner.privateRun(SuiteRunner.java:383)
at org.testng.SuiteRunner.run(SuiteRunner.java:326)
at org.testng.SuiteRunnerWorker.runSuite(SuiteRunnerWorker.java:52)
at org.testng.SuiteRunnerWorker.run(SuiteRunnerWorker.java:95)
at org.testng.TestNG.runSuitesSequentially(TestNG.java:1249)
at org.testng.TestNG.runSuitesLocally(TestNG.java:1169)
at org.testng.TestNG.runSuites(TestNG.java:1092)
at org.testng.TestNG.run(TestNG.java:1060)
at org.testng.remote.AbstractRemoteTestNG.run(AbstractRemoteTestNG.java:115)
at org.testng.remote.RemoteTestNG.initAndRun(RemoteTestNG.java:251)
at org.testng.remote.RemoteTestNG.main(RemoteTestNG.java:77)
]]>
            </full-stacktrace>
          </exception> <!-- java.lang.Throwable -->
          <reporter-output>
          </reporter-output>
        </test-method> <!-- Fill_Form_with_Invalid_info -->
        <test-method signature="Capture_ErrorMessage()[pri:7, instance:testNG.MainTestng@6e9319f]" started-at="2024-02-28T16:35:44 IST" name="Capture_ErrorMessage" finished-at="2024-02-28T16:35:44 IST" depends-on-methods="testNG.MainTestng.Fill_Form_with_Invalid_info" duration-ms="0" status="SKIP">
          <exception class="java.lang.Throwable">
            <message>
              <![CDATA[Method MainTestng.Capture_ErrorMessage()[pri:7, instance:testNG.MainTestng@6e9319f] depends on not successfully finished methods]]>
            </message>
            <full-stacktrace>
              <![CDATA[java.lang.Throwable: Method MainTestng.Capture_ErrorMessage()[pri:7, instance:testNG.MainTestng@6e9319f] depends on not successfully finished methods
at org.testng.internal.invokers.TestInvoker.invokeTestMethods(TestInvoker.java:148)
at org.testng.internal.invokers.TestMethodWorker.invokeTestMethods(TestMethodWorker.java:146)
at org.testng.internal.invokers.TestMethodWorker.run(TestMethodWorker.java:128)
at java.base/java.util.ArrayList.forEach(ArrayList.java:1511)
at org.testng.TestRunner.privateRun(TestRunner.java:808)
at org.testng.TestRunner.run(TestRunner.java:603)
at org.testng.SuiteRunner.runTest(SuiteRunner.java:429)
at org.testng.SuiteRunner.runSequentially(SuiteRunner.java:423)
at org.testng.SuiteRunner.privateRun(SuiteRunner.java:383)
at org.testng.SuiteRunner.run(SuiteRunner.java:326)
at org.testng.SuiteRunnerWorker.runSuite(SuiteRunnerWorker.java:52)
at org.testng.SuiteRunnerWorker.run(SuiteRunnerWorker.java:95)
at org.testng.TestNG.runSuitesSequentially(TestNG.java:1249)
at org.testng.TestNG.runSuitesLocally(TestNG.java:1169)
at org.testng.TestNG.runSuites(TestNG.java:1092)
at org.testng.TestNG.run(TestNG.java:1060)
at org.testng.remote.AbstractRemoteTestNG.run(AbstractRemoteTestNG.java:115)
at org.testng.remote.RemoteTestNG.initAndRun(RemoteTestNG.java:251)
at org.testng.remote.RemoteTestNG.main(RemoteTestNG.java:77)
]]>
            </full-stacktrace>
          </exception> <!-- java.lang.Throwable -->
          <reporter-output>
          </reporter-output>
        </test-method> <!-- Capture_ErrorMessage -->
        <test-method signature="Fill_Form_with_Valid_data(java.lang.String,java.lang.String,java.lang.String,java.lang.String,java.lang.String,java.lang.String,java.lang.String,java.lang.String)[pri:8, instance:testNG.MainTestng@6e9319f]" started-at="2024-02-28T16:35:44 IST" name="Fill_Form_with_Valid_data" finished-at="2024-02-28T16:35:44 IST" depends-on-methods="testNG.MainTestng.Capture_ErrorMessage" duration-ms="0" status="SKIP">
          <exception class="java.lang.Throwable">
            <message>
              <![CDATA[Method MainTestng.Fill_Form_with_Valid_data(java.lang.String,java.lang.String,java.lang.String,java.lang.String,java.lang.String,java.lang.String,java.lang.String,java.lang.String)[pri:8, instance:testNG.MainTestng@6e9319f] depends on not successfully finished methods]]>
            </message>
            <full-stacktrace>
              <![CDATA[java.lang.Throwable: Method MainTestng.Fill_Form_with_Valid_data(java.lang.String,java.lang.String,java.lang.String,java.lang.String,java.lang.String,java.lang.String,java.lang.String,java.lang.String)[pri:8, instance:testNG.MainTestng@6e9319f] depends on not successfully finished methods
at org.testng.internal.invokers.TestInvoker.invokeTestMethods(TestInvoker.java:148)
at org.testng.internal.invokers.TestMethodWorker.invokeTestMethods(TestMethodWorker.java:146)
at org.testng.internal.invokers.TestMethodWorker.run(TestMethodWorker.java:128)
at java.base/java.util.ArrayList.forEach(ArrayList.java:1511)
at org.testng.TestRunner.privateRun(TestRunner.java:808)
at org.testng.TestRunner.run(TestRunner.java:603)
at org.testng.SuiteRunner.runTest(SuiteRunner.java:429)
at org.testng.SuiteRunner.runSequentially(SuiteRunner.java:423)
at org.testng.SuiteRunner.privateRun(SuiteRunner.java:383)
at org.testng.SuiteRunner.run(SuiteRunner.java:326)
at org.testng.SuiteRunnerWorker.runSuite(SuiteRunnerWorker.java:52)
at org.testng.SuiteRunnerWorker.run(SuiteRunnerWorker.java:95)
at org.testng.TestNG.runSuitesSequentially(TestNG.java:1249)
at org.testng.TestNG.runSuitesLocally(TestNG.java:1169)
at org.testng.TestNG.runSuites(TestNG.java:1092)
at org.testng.TestNG.run(TestNG.java:1060)
at org.testng.remote.AbstractRemoteTestNG.run(AbstractRemoteTestNG.java:115)
at org.testng.remote.RemoteTestNG.initAndRun(RemoteTestNG.java:251)
at org.testng.remote.RemoteTestNG.main(RemoteTestNG.java:77)
]]>
            </full-stacktrace>
          </exception> <!-- java.lang.Throwable -->
          <reporter-output>
          </reporter-output>
        </test-method> <!-- Fill_Form_with_Valid_data -->
        <test-method signature="Validate_Entered_Details()[pri:9, instance:testNG.MainTestng@6e9319f]" started-at="2024-02-28T16:35:44 IST" name="Validate_Entered_Details" finished-at="2024-02-28T16:35:44 IST" depends-on-methods="testNG.MainTestng.Fill_Form_with_Valid_data" duration-ms="0" status="SKIP">
          <exception class="java.lang.Throwable">
            <message>
              <![CDATA[Method MainTestng.Validate_Entered_Details()[pri:9, instance:testNG.MainTestng@6e9319f] depends on not successfully finished methods]]>
            </message>
            <full-stacktrace>
              <![CDATA[java.lang.Throwable: Method MainTestng.Validate_Entered_Details()[pri:9, instance:testNG.MainTestng@6e9319f] depends on not successfully finished methods
at org.testng.internal.invokers.TestInvoker.invokeTestMethods(TestInvoker.java:148)
at org.testng.internal.invokers.TestMethodWorker.invokeTestMethods(TestMethodWorker.java:146)
at org.testng.internal.invokers.TestMethodWorker.run(TestMethodWorker.java:128)
at java.base/java.util.ArrayList.forEach(ArrayList.java:1511)
at org.testng.TestRunner.privateRun(TestRunner.java:808)
at org.testng.TestRunner.run(TestRunner.java:603)
at org.testng.SuiteRunner.runTest(SuiteRunner.java:429)
at org.testng.SuiteRunner.runSequentially(SuiteRunner.java:423)
at org.testng.SuiteRunner.privateRun(SuiteRunner.java:383)
at org.testng.SuiteRunner.run(SuiteRunner.java:326)
at org.testng.SuiteRunnerWorker.runSuite(SuiteRunnerWorker.java:52)
at org.testng.SuiteRunnerWorker.run(SuiteRunnerWorker.java:95)
at org.testng.TestNG.runSuitesSequentially(TestNG.java:1249)
at org.testng.TestNG.runSuitesLocally(TestNG.java:1169)
at org.testng.TestNG.runSuites(TestNG.java:1092)
at org.testng.TestNG.run(TestNG.java:1060)
at org.testng.remote.AbstractRemoteTestNG.run(AbstractRemoteTestNG.java:115)
at org.testng.remote.RemoteTestNG.initAndRun(RemoteTestNG.java:251)
at org.testng.remote.RemoteTestNG.main(RemoteTestNG.java:77)
]]>
            </full-stacktrace>
          </exception> <!-- java.lang.Throwable -->
          <reporter-output>
          </reporter-output>
        </test-method> <!-- Validate_Entered_Details -->
        <test-method is-config="true" signature="close()[pri:0, instance:testNG.MainTestng@6e9319f]" started-at="2024-02-28T16:35:44 IST" name="close" finished-at="2024-02-28T16:35:45 IST" duration-ms="1109" status="PASS">
          <reporter-output>
          </reporter-output>
        </test-method> <!-- close -->
      </class> <!-- testNG.MainTestng -->
    </test> <!-- UrbanLadderTestCases -->
  </suite> <!-- Urban_Ladder_Suite -->
</testng-results>
